{"name": "test_failed", "status": "failed", "statusDetails": {"message": "AssertionError: This test passed or failed randomly\nassert False\n +  where False = choice([True, False])\n +    where choice = random.choice", "trace": "def test_failed():\n>       assert random.choice([True, False]), \"This test passed or failed randomly\"\nE       AssertionError: This test passed or failed randomly\nE       assert False\nE        +  where False = choice([True, False])\nE        +    where choice = random.choice\n\ntests/pytest_doc/how_to/test_status.py:11: AssertionError"}, "start": 1751508403567, "stop": 1751508403568, "uuid": "c8588b8a-60fe-4af7-a725-b445df72ab9f", "historyId": "6cea12f52f70a5b97f9e12b470644a45", "testCaseId": "6cea12f52f70a5b97f9e12b470644a45", "fullName": "tests.pytest_doc.how_to.test_status#test_failed", "labels": [{"name": "parentSuite", "value": "tests.pytest_doc.how_to"}, {"name": "suite", "value": "test_status"}, {"name": "host", "value": "pkrvmbietmlfzoi"}, {"name": "thread", "value": "2519-MainThread"}, {"name": "framework", "value": "pytest"}, {"name": "language", "value": "cpython3"}, {"name": "package", "value": "tests.pytest_doc.how_to.test_status"}]}