{"name": "test_failed", "status": "failed", "statusDetails": {"message": "AssertionError: This test passed or failed randomly\nassert False\n +  where False = choice([True, False])\n +    where choice = random.choice", "trace": "def test_failed():\n>       assert random.choice([True, False]), \"This test passed or failed randomly\"\nE       AssertionError: This test passed or failed randomly\nE       assert False\nE        +  where False = choice([True, False])\nE        +    where choice = random.choice\n\ntests/pytest_doc/how_to/test_status.py:11: AssertionError"}, "start": 1751518993161, "stop": 1751518993162, "uuid": "c5d210d3-4fb1-466c-9788-a3ed5793dc24", "historyId": "6cea12f52f70a5b97f9e12b470644a45", "testCaseId": "6cea12f52f70a5b97f9e12b470644a45", "fullName": "tests.pytest_doc.how_to.test_status#test_failed", "labels": [{"name": "parentSuite", "value": "tests.pytest_doc.how_to"}, {"name": "suite", "value": "test_status"}, {"name": "host", "value": "pkrvmbietmlfzoi"}, {"name": "thread", "value": "2393-MainThread"}, {"name": "framework", "value": "pytest"}, {"name": "language", "value": "cpython3"}, {"name": "package", "value": "tests.pytest_doc.how_to.test_status"}]}